Workbook
Name Slicer_Discount_caategory: #N/A
Name Slicer_price_category: #N/A
Name Slicer_Rating_category: #N/A

Sheet Dashboard

Sheet Raw_data
A1: Product | B1: Current price | C1: old price | D1: Discount | E1: Review | F1: Ratingd
A2: 115 Piece Set Of Multifunctional Precision Screwdrivers | B2: KSh 950 | C2: KSh 1,525 | D2: 0.38 | E2: -2 | F2: 4.5 out of 5
A3: Metal Decorative Hooks Key Hangers Entryway Wall Hooks Towel Hooks - Home | B3: KSh 527 | C3: KSh 999 | D3: 0.47 | E3: -14 | F3: 4.1 out of 5
A4: Portable Mini Cordless Car Vacuum Cleaner - Blue | B4: KSh 2,199 | C4: KSh 2,923 | D4: 0.25 | E4: -24 | F4: 4.6 out of 5
A5: Weighing Scale Digital Bathroom Body Fat Scale USB-Black | B5: KSh 1,580 | C5: KSh 2,499 | D5: 0.37 | E5: -7 | F5: 4.7 out of 5
A6: Portable Home Small Air Humidifier 3-Speed Fan - Green | B6: KSh 1,740 | C6: KSh 2,356 | D6: 0.26 | E6: -5 | F6: 4.8 out of 5
A7: 220V 60W Electric Soldering Iron Kits With Tools, Tips, And Multimeter | B7: KSh 2,999 | C7: KSh 3,290 | D7: 0.09 | E7: -15 | F7: 4 out of 5
A8: 137 Pieces Cake Decorating Tool Set Baking Supplies | B8: KSh 2,319 | C8: KSh 3,032 | D8: 0.24 | E8: -55 | F8: 4.6 out of 5
A9: Desk Foldable Fan Adjustable Fan Strong Wind 3 Gear Usb | B9: KSh 988 | C9: KSh 1,580 | D9: 0.37 | E9: -2 | F9: 4 out of 5
A10: LASA FOLDING TABLE SERVING STAND | B10: KSh 1,274 | C10: KSh 2,800 | D10: 0.55 | E10: -5 | F10: 4.8 out of 5
A11: 13 In 1 Home Repair Tools Box Kit Set | B11: KSh 1,600 | C11: KSh 2,929 | D11: 0.45 | E11: -5 | F11: 3.8 out of 5
A12: Genebre 115 In 1 Screwdriver Repairing Tool Set For IPhone Cellphone Hand Tool | B12: KSh 799 | C12: KSh 999 | D12: 0.2 | E12: -12 | F12: 4.1 out of 5
A13: 100 Pcs Crochet Hook Tool Set Knitting Hook Set With Box | B13: KSh 990 | C13: KSh 1,500 | D13: 0.34 | E13: -39 | F13: 4.7 out of 5
... A22: 3PCS Single Head Knitting Crochet Sweater Needle Set | B22: KSh 38 | C22: KSh 80 | D22: 0.53 | E22: -13 | F22: 3.3 out of 5
A23: 4pcs Bathroom/Kitchen Towel Rack,Roll Paper Holder,Towel Bars,Hook | B23: KSh 1,860 | C23: KSh 3,220 | D23: 0.42
A24: LED Romantic Spaceship Starry Sky Projector,Children's Bedroom Night Light-Blue | B24: KSh 880 | C24: KSh 1,350 | D24: 0.35 | E24: -6 | F24: 4 out of 5
A25: Foldable Overbed Table/Desk | B25: KSh 1,650 | C25: KSh 2,150 | D25: 0.23 | E25: -14 | F25: 4.4 out of 5
A26: LASA 3 Tier Bamboo Shoe Bench Storage Shelf | B26: KSh 2,048 | C26: KSh 4,500 | D26: 0.54 | E26: -7 | F26: 4.3 out of 5
A27: Electronic Digital Display Vernier Caliper | B27: KSh 420 | C27: KSh 647 | D27: 0.35 | E27: -49 | F27: 4.6 out of 5
A28: Portable Wardrobe Nonwoven With 3 Hanging Rods And 6 Storage Shelves | B28: KSh 2,880 | C28: KSh 3,520 | D28: 0.18 | E28: -12 | F28: 3.8 out of 5
A29: 12 Litre Black Insulated Lunch Box | B29: KSh 1,350 | C29: KSh 1,990 | D29: 0.32 | E29: -13 | F29: 3.8 out of 5
A30: 52 Pieces Cake Decorating Tool Set Gift Kit Baking Supplies | B30: KSh 1,758 | C30: KSh 2,499 | D30: 0.3 | E30: -20 | F30: 4.1 out of 5
A31: MultiFunctional Storage Rack Multi-layer Bookshelf | B31: KSh 2,200 | C31: KSh 4,080 | D31: 0.46
A32: Exfoliate And Exfoliate Face Towel - Black | B32: KSh 185 | C32: KSh 382 | D32: 0.52 | E32: -9 | F32: 4.3 out of 5
A33: 12 Litre Insulated Lunch Box Grey | B33: KSh 980 | C33: KSh 1,490 | D33: 0.34 | E33: -12 | F33: 4.7 out of 5
A34: LED Eye Protection Desk Lamp , Study, Reading, USB Fan - Double Pen Holder | B34: KSh 1,820 | C34: KSh 3,490 | D34: 0.48 | E34: -9 | F34: 4.3 out of 5
A35: 53Pcs/Set Yarn Knitting Crochet Hooks With Bag - Fortune Cat | B35: KSh 1,940 | C35: KSh 2,650 | D35: 0.27 | E35: -20 | F35: 4.7 out of 5
A36: 53 Pieces/Set Yarn Knitting Crochet Hooks With Bag - Pansies | B36: KSh 1,980 | C36: KSh 2,699 | D36: 0.27 | E36: -32 | F36: 4.5 out of 5
A37: DIY File Folder, Office Drawer File Holder, Pen Holder, Desktop Storage Rack | B37: KSh 1,620 | C37: KSh 2,690 | D37: 0.4 | E37: -1 | F37: 5 out of 5
A38: Classic Black Cat Cotton Hemp Pillow Case For Home Car | B38: KSh 171 | C38: KSh 360 | D38: 0.53 | E38: -2 | F38: 5 out of 5
A39: Punch-free Great Load Bearing Bathroom Storage Rack Wall Shelf-White | B39: KSh 389 | C39: KSh 656 | D39: 0.41 | E39: -36 | F39: 4.3 out of 5
A40: 1/2/3 Seater Elastic Sofa Cover,Living Room/Home Decor Chair Cover-Grey | B40: KSh 1,620 - KSh 1,980 | C40: KSh 2,200 - KSh 3,200 | D40: 0.38 | E40: -2 | F40: 4.5 out of 5
A41: LASA Stainless Steel Double Wall Mount Soap Dispenser - 500ml | B41: KSh 2,750 | C41: KSh 4,471 | D41: 0.38
A42: 4M Float Switch Water Level Controller -Water Tank | B42: KSh 475 | C42: KSh 931 | D42: 0.49
A43: Modern Sofa Throw Pillow Cover-45x45cm-Blue&Red | B43: KSh 238 | C43: KSh 476 | D43: 0.5
A44: Balloon Insert, Birthday Party Balloon Set, PU Leather | B44: KSh 610 | C44: KSh 1,060 | D44: 0.42
A45: Balloon Insert, Birthday Party Balloon Set, PU Leather | B45: KSh 610 | C45: KSh 1,060 | D45: 0.42
A46: Shower Cap Wide Elastic Band Cover Reusable Bashroom Cap | B46: KSh 2,132 | C46: KSh 2,169 | D46: 0.02
A47: Christmas Elk Fence Yard Lawn Decorations Cute For Holidays | B47: KSh 999 | C47: KSh 2,000 | D47: 0.5
A48: 60W Hot Melt Glue Sprayer - Efficient And Stable Glue Dispensing | B48: KSh 1,190 | C48: KSh 1,785 | D48: 0.33
...

Sheet Top_Rating
A3: Row Labels | B3: Average of Rating
A4: 40cm Gold DIY Acrylic Wall Sticker Clock | B4: 4.8
A5: Anti-Skid Absorbent Insulation Coaster For Home Office | B5: 5
A6: Bedroom Simple Floor Hanging Clothes Rack Single Pole Hat Rack - White | B6: 5
A7: Classic Black Cat Cotton Hemp Pillow Case For Home Car | B7: 5
A8: DIY File Folder, Office Drawer File Holder, Pen Holder, Desktop Storage Rack | B8: 5
A9: Konka Healty Electric Kettle, 24-hour Heat Preservation,1.5L,800W, White | B9: 5
A10: LASA Aluminum Folding Truck Hand Cart - 68kg Max | B10: 5
A11: LASA FOLDING TABLE SERVING STAND | B11: 4.8
A12: Peacock Throw Pillow Cushion Case For Home Car | B12: 5
A13: Portable Home Small Air Humidifier 3-Speed Fan - Green | B13: 4.8
A14: Grand Total | B14: 4.94

Sheet Top_Reviews
A3: Row Labels | B3: Sum of Review
A4: 100 Pcs Crochet Hook Tool Set Knitting Hook Set With Box | B4: 39
A5: 120W Cordless Vacuum Cleaners Handheld Electric Vacuum Cleaner | B5: 69
A6: 137 Pieces Cake Decorating Tool Set Baking Supplies | B6: 55
A7: 3D Waterproof EVA Plastic Shower Curtain 1.8*2Mtrs | B7: 44
A8: 52 Pieces Cake Decorating Tool Set Gift Kit Baking Supplies | B8: 20
A9: 53 Pieces/Set Yarn Knitting Crochet Hooks With Bag - Pansies | B9: 32
A10: 53Pcs/Set Yarn Knitting Crochet Hooks With Bag - Fortune Cat | B10: 20
A11: Electronic Digital Display Vernier Caliper | B11: 49
A12: Portable Mini Cordless Car Vacuum Cleaner - Blue | B12: 24
A13: Punch-free Great Load Bearing Bathroom Storage Rack Wall Shelf-White | B13: 36
A14: Grand Total | B14: 388

Sheet Top_Discount
A3: Row Labels | B3: Average of Discount
A4: 3PCS Single Head Knitting Crochet Sweater Needle Set | B4: 0.53
A5: 5-PCS Stainless Steel Cooking Pot Set With Steamed Slices | B5: 0.55
A6: 6 In 1 Bottle Can Opener Multifunctional Easy Opener | B6: 0.64
A7: Classic Black Cat Cotton Hemp Pillow Case For Home Car | B7: 0.53
A8: Creative Owl Shape Keychain Black | B8: 0.55
A9: Exfoliate And Exfoliate Face Towel - Black | B9: 0.52
A10: Intelligent LED Body Sensor Wireless Lighting Night Light USB | B10: 0.52
A11: LASA 3 Tier Bamboo Shoe Bench Storage Shelf | B11: 0.54
A12: LASA FOLDING TABLE SERVING STAND | B12: 0.55
A13: Mythco 120COB Solar Wall Ligt With Motion Sensor And Remote Control 3 Modes | B13: 0.54
A14: Grand Total | B14: 0.54727273

Sheet Discount_vs_Reviews
A3: Row Labels | B3: Average of Review
A4: Medium Discount | B4: 15.909091
A5: High Discount | B5: 10.806452
A6: Low Discount | B6: 9.5
A7: Grand Total | B7: 12.684211

Sheet Rating_vs_Reviews
A3: Row Labels | B3: Average of Review
A4: Average | B4: 7.6666667
A5: Excellent | B5: 13.472222
A6: Not Rated
A7: Poor | B7: 14.083333
A8: Grand Total | B8: 12.684211

Sheet Price_vs_Rating
A3: Row Labels | B3: Average of Rating
A4: High | B4: 4.1130435
A5: Low | B5: 3.5307692
A6: Medium | B6: 3.8526316
A7: Premium | B7: 4
A8: Grand Total | B8: 3.8894737

Sheet Rating_category
A3: Row Labels | B3: Count of Product
A4: Average | B4: 9
A5: Excellent | B5: 36
A6: Not Rated | B6: 55
A7: Poor | B7: 12
A8: Grand Total | B8: 112

Sheet Discount_Category
A3: Row Labels | B3: Count of Product
A4: Medium Discount | B4: 31
A5: High Discount | B5: 63
A6: Low Discount | B6: 18
A7: Grand Total | B7: 112

Sheet Cleaned_data
A1: Product | B1: Current price | C1: Old prices | D1: Discount_price | E1: Discount | F1: Review | G1: Rating | H1: Review_Category | I1: Rating_category | J1: Discount_caategory | K1: price_category
A2: 115 Piece Set Of Multifunctional Precision Screwdrivers | B2: 950 | C2: 1525 | D2: 575 | E2: 0.38 | F2: 2 | G2: 4.5 | H2: =IF(F2="","No reviews",IF(F2>=20,"High",IF(F2>=5,"Medium","Low"))) -> Low | I2: =IF(G2="","Not Rated",IF(G2<3,"Poor",IF(G2<4,"Average","Excellent"))) -> Excellent | J2: =IF(E2<0.2,"Low Discount",IF(E2<0.4,"Medium Discount","High Discount")) -> Medium Discount | K2: =IF(B2<500,"Low",IF(B2<1500,"Medium",IF(B2<3000,"High","Premium"))) -> Medium
A3: Metal Decorative Hooks Key Hangers Entryway Wall Hooks Towel Hooks - Home | B3: 527 | C3: 999 | D3: 472 | E3: 0.47 | F3: 14 | G3: 4.1 | H3: =IF(F3="","No reviews",IF(F3>=20,"High",IF(F3>=5,"Medium","Low"))) -> Medium | I3: =IF(G3="","Not Rated",IF(G3<3,"Poor",IF(G3<4,"Average","Excellent"))) -> Excellent | J3: =IF(E3<0.2,"Low Discount",IF(E3<0.4,"Medium Discount","High Discount")) -> High Discount | K3: =IF(B3<500,"Low",IF(B3<1500,"Medium",IF(B3<3000,"High","Premium"))) -> Medium
A4: Portable Mini Cordless Car Vacuum Cleaner - Blue | B4: 2199 | C4: 2923 | D4: 724 | E4: 0.25 | F4: 24 | G4: 4.6 | H4: =IF(F4="","No reviews",IF(F4>=20,"High",IF(F4>=5,"Medium","Low"))) -> High | I4: =IF(G4="","Not Rated",IF(G4<3,"Poor",IF(G4<4,"Average","Excellent"))) -> Excellent | J4: =IF(E4<0.2,"Low Discount",IF(E4<0.4,"Medium Discount","High Discount")) -> Medium Discount | K4: =IF(B4<500,"Low",IF(B4<1500,"Medium",IF(B4<3000,"High","Premium"))) -> High
A5: Weighing Scale Digital Bathroom Body Fat Scale USB-Black | B5: 1580 | C5: 2499 | D5: 919 | E5: 0.37 | F5: 7 | G5: 4.7 | H5: =IF(F5="","No reviews",IF(F5>=20,"High",IF(F5>=5,"Medium","Low"))) -> Medium | I5: =IF(G5="","Not Rated",IF(G5<3,"Poor",IF(G5<4,"Average","Excellent"))) -> Excellent | J5: =IF(E5<0.2,"Low Discount",IF(E5<0.4,"Medium Discount","High Discount")) -> Medium Discount | K5: =IF(B5<500,"Low",IF(B5<1500,"Medium",IF(B5<3000,"High","Premium"))) -> High
A6: Portable Home Small Air Humidifier 3-Speed Fan - Green | B6: 1740 | C6: 2356 | D6: 616 | E6: 0.26 | F6: 5 | G6: 4.8 | H6: =IF(F6="","No reviews",IF(F6>=20,"High",IF(F6>=5,"Medium","Low"))) -> Medium | I6: =IF(G6="","Not Rated",IF(G6<3,"Poor",IF(G6<4,"Average","Excellent"))) -> Excellent | J6: =IF(E6<0.2,"Low Discount",IF(E6<0.4,"Medium Discount","High Discount")) -> Medium Discount | K6: =IF(B6<500,"Low",IF(B6<1500,"Medium",IF(B6<3000,"High","Premium"))) -> High
A7: 220V 60W Electric Soldering Iron Kits With Tools, Tips, And Multimeter | B7: 2999 | C7: 3290 | D7: 291 | E7: 0.09 | F7: 15 | G7: 4 | H7: =IF(F7="","No reviews",IF(F7>=20,"High",IF(F7>=5,"Medium","Low"))) -> Medium | I7: =IF(G7="","Not Rated",IF(G7<3,"Poor",IF(G7<4,"Average","Excellent"))) -> Excellent | J7: =IF(E7<0.2,"Low Discount",IF(E7<0.4,"Medium Discount","High Discount")) -> Low Discount | K7: =IF(B7<500,"Low",IF(B7<1500,"Medium",IF(B7<3000,"High","Premium"))) -> High
A8: 137 Pieces Cake Decorating Tool Set Baking Supplies | B8: 2319 | C8: 3032 | D8: 713 | E8: 0.24 | F8: 55 | G8: 4.6 | H8: =IF(F8="","No reviews",IF(F8>=20,"High",IF(F8>=5,"Medium","Low"))) -> High | I8: =IF(G8="","Not Rated",IF(G8<3,"Poor",IF(G8<4,"Average","Excellent"))) -> Excellent | J8: =IF(E8<0.2,"Low Discount",IF(E8<0.4,"Medium Discount","High Discount")) -> Medium Discount | K8: =IF(B8<500,"Low",IF(B8<1500,"Medium",IF(B8<3000,"High","Premium"))) -> High
A9: Desk Foldable Fan Adjustable Fan Strong Wind 3 Gear Usb | B9: 988 | C9: 1580 | D9: 592 | E9: 0.37 | F9: 2 | G9: 4 | H9: =IF(F9="","No reviews",IF(F9>=20,"High",IF(F9>=5,"Medium","Low"))) -> Low | I9: =IF(G9="","Not Rated",IF(G9<3,"Poor",IF(G9<4,"Average","Excellent"))) -> Excellent | J9: =IF(E9<0.2,"Low Discount",IF(E9<0.4,"Medium Discount","High Discount")) -> Medium Discount | K9: =IF(B9<500,"Low",IF(B9<1500,"Medium",IF(B9<3000,"High","Premium"))) -> Medium
A10: LASA FOLDING TABLE SERVING STAND | B10: 1274 | C10: 2800 | D10: 1526 | E10: 0.55 | F10: 5 | G10: 4.8 | H10: =IF(F10="","No reviews",IF(F10>=20,"High",IF(F10>=5,"Medium","Low"))) -> Medium | I10: =IF(G10="","Not Rated",IF(G10<3,"Poor",IF(G10<4,"Average","Excellent"))) -> Excellent | J10: =IF(E10<0.2,"Low Discount",IF(E10<0.4,"Medium Discount","High Discount")) -> High Discount | K10: =IF(B10<500,"Low",IF(B10<1500,"Medium",IF(B10<3000,"High","Premium"))) -> Medium
A11: 13 In 1 Home Repair Tools Box Kit Set | B11: 1600 | C11: 2929 | D11: 1329 | E11: 0.45 | F11: 5 | G11: 3.8 | H11: =IF(F11="","No reviews",IF(F11>=20,"High",IF(F11>=5,"Medium","Low"))) -> Medium | I11: =IF(G11="","Not Rated",IF(G11<3,"Poor",IF(G11<4,"Average","Excellent"))) -> Average | J11: =IF(E11<0.2,"Low Discount",IF(E11<0.4,"Medium Discount","High Discount")) -> High Discount | K11: =IF(B11<500,"Low",IF(B11<1500,"Medium",IF(B11<3000,"High","Premium"))) -> High
A12: Genebre 115 In 1 Screwdriver Repairing Tool Set For IPhone Cellphone Hand Tool | B12: 799 | C12: 999 | D12: 200 | E12: 0.2 | F12: 12 | G12: 4.1 | H12: =IF(F12="","No reviews",IF(F12>=20,"High",IF(F12>=5,"Medium","Low"))) -> Medium | I12: =IF(G12="","Not Rated",IF(G12<3,"Poor",IF(G12<4,"Average","Excellent"))) -> Excellent | J12: =IF(E12<0.2,"Low Discount",IF(E12<0.4,"Medium Discount","High Discount")) -> Medium Discount | K12: =IF(B12<500,"Low",IF(B12<1500,"Medium",IF(B12<3000,"High","Premium"))) -> Medium
A13: 100 Pcs Crochet Hook Tool Set Knitting Hook Set With Box | B13: 990 | C13: 1500 | D13: 510 | E13: 0.34 | F13: 39 | G13: 4.7 | H13: =IF(F13="","No reviews",IF(F13>=20,"High",IF(F13>=5,"Medium","Low"))) -> High | I13: =IF(G13="","Not Rated",IF(G13<3,"Poor",IF(G13<4,"Average","Excellent"))) -> Excellent | J13: =IF(E13<0.2,"Low Discount",IF(E13<0.4,"Medium Discount","High Discount")) -> Medium Discount | K13: =IF(B13<500,"Low",IF(B13<1500,"Medium",IF(B13<3000,"High","Premium"))) -> Medium
... A22: 3PCS Single Head Knitting Crochet Sweater Needle Set | B22: 38 | C22: 80 | D22: 42 | E22: 0.53 | F22: 13 | G22: 3.3 | H22: =IF(F22="","No reviews",IF(F22>=20,"High",IF(F22>=5,"Medium","Low"))) -> Medium | I22: =IF(G22="","Not Rated",IF(G22<3,"Poor",IF(G22<4,"Average","Excellent"))) -> Average | J22: =IF(E22<0.2,"Low Discount",IF(E22<0.4,"Medium Discount","High Discount")) -> High Discount | K22: =IF(B22<500,"Low",IF(B22<1500,"Medium",IF(B22<3000,"High","Premium"))) -> Low
A23: 4pcs Bathroom/Kitchen Towel Rack,Roll Paper Holder,Towel Bars,Hook | B23: 1860 | C23: 3220 | D23: 1360 | E23: 0.42 | H23: =IF(F23="","No reviews",IF(F23>=20,"High",IF(F23>=5,"Medium","Low"))) -> No reviews | I23: =IF(G23="","Not Rated",IF(G23<3,"Poor",IF(G23<4,"Average","Excellent"))) -> Not Rated | J23: =IF(E23<0.2,"Low Discount",IF(E23<0.4,"Medium Discount","High Discount")) -> High Discount | K23: =IF(B23<500,"Low",IF(B23<1500,"Medium",IF(B23<3000,"High","Premium"))) -> High
A24: LED Romantic Spaceship Starry Sky Projector,Children's Bedroom Night Light-Blue | B24: 880 | C24: 1350 | D24: 470 | E24: 0.35 | F24: 6 | G24: 4 | H24: =IF(F24="","No reviews",IF(F24>=20,"High",IF(F24>=5,"Medium","Low"))) -> Medium | I24: =IF(G24="","Not Rated",IF(G24<3,"Poor",IF(G24<4,"Average","Excellent"))) -> Excellent | J24: =IF(E24<0.2,"Low Discount",IF(E24<0.4,"Medium Discount","High Discount")) -> Medium Discount | K24: =IF(B24<500,"Low",IF(B24<1500,"Medium",IF(B24<3000,"High","Premium"))) -> Medium
A25: Foldable Overbed Table/Desk | B25: 1650 | C25: 2150 | D25: 500 | E25: 0.23 | F25: 14 | G25: 4.4 | H25: =IF(F25="","No reviews",IF(F25>=20,"High",IF(F25>=5,"Medium","Low"))) -> Medium | I25: =IF(G25="","Not Rated",IF(G25<3,"Poor",IF(G25<4,"Average","Excellent"))) -> Excellent | J25: =IF(E25<0.2,"Low Discount",IF(E25<0.4,"Medium Discount","High Discount")) -> Medium Discount | K25: =IF(B25<500,"Low",IF(B25<1500,"Medium",IF(B25<3000,"High","Premium"))) -> High
A26: LASA 3 Tier Bamboo Shoe Bench Storage Shelf | B26: 2048 | C26: 4500 | D26: 2452 | E26: 0.54 | F26: 7 | G26: 4.3 | H26: =IF(F26="","No reviews",IF(F26>=20,"High",IF(F26>=5,"Medium","Low"))) -> Medium | I26: =IF(G26="","Not Rated",IF(G26<3,"Poor",IF(G26<4,"Average","Excellent"))) -> Excellent | J26: =IF(E26<0.2,"Low Discount",IF(E26<0.4,"Medium Discount","High Discount")) -> High Discount | K26: =IF(B26<500,"Low",IF(B26<1500,"Medium",IF(B26<3000,"High","Premium"))) -> High
A27: Electronic Digital Display Vernier Caliper | B27: 420 | C27: 647 | D27: 227 | E27: 0.35 | F27: 49 | G27: 4.6 | H27: =IF(F27="","No reviews",IF(F27>=20,"High",IF(F27>=5,"Medium","Low"))) -> High | I27: =IF(G27="","Not Rated",IF(G27<3,"Poor",IF(G27<4,"Average","Excellent"))) -> Excellent | J27: =IF(E27<0.2,"Low Discount",IF(E27<0.4,"Medium Discount","High Discount")) -> Medium Discount | K27: =IF(B27<500,"Low",IF(B27<1500,"Medium",IF(B27<3000,"High","Premium"))) -> Low
A28: Portable Wardrobe Nonwoven With 3 Hanging Rods And 6 Storage Shelves | B28: 2880 | C28: 3520 | D28: 640 | E28: 0.18 | F28: 12 | G28: 3.8 | H28: =IF(F28="","No reviews",IF(F28>=20,"High",IF(F28>=5,"Medium","Low"))) -> Medium | I28: =IF(G28="","Not Rated",IF(G28<3,"Poor",IF(G28<4,"Average","Excellent"))) -> Average | J28: =IF(E28<0.2,"Low Discount",IF(E28<0.4,"Medium Discount","High Discount")) -> Low Discount | K28: =IF(B28<500,"Low",IF(B28<1500,"Medium",IF(B28<3000,"High","Premium"))) -> High
A29: 12 Litre Black Insulated Lunch Box | B29: 1350 | C29: 1990 | D29: 640 | E29: 0.32 | F29: 13 | G29: 3.8 | H29: =IF(F29="","No reviews",IF(F29>=20,"High",IF(F29>=5,"Medium","Low"))) -> Medium | I29: =IF(G29="","Not Rated",IF(G29<3,"Poor",IF(G29<4,"Average","Excellent"))) -> Average | J29: =IF(E29<0.2,"Low Discount",IF(E29<0.4,"Medium Discount","High Discount")) -> Medium Discount | K29: =IF(B29<500,"Low",IF(B29<1500,"Medium",IF(B29<3000,"High","Premium"))) -> Medium
A30: 52 Pieces Cake Decorating Tool Set Gift Kit Baking Supplies | B30: 1758 | C30: 2499 | D30: 741 | E30: 0.3 | F30: 20 | G30: 4.1 | H30: =IF(F30="","No reviews",IF(F30>=20,"High",IF(F30>=5,"Medium","Low"))) -> High | I30: =IF(G30="","Not Rated",IF(G30<3,"Poor",IF(G30<4,"Average","Excellent"))) -> Excellent | J30: =IF(E30<0.2,"Low Discount",IF(E30<0.4,"Medium Discount","High Discount")) -> Medium Discount | K30: =IF(B30<500,"Low",IF(B30<1500,"Medium",IF(B30<3000,"High","Premium"))) -> High
A31: MultiFunctional Storage Rack Multi-layer Bookshelf | B31: 2200 | C31: 4080 | D31: 1880 | E31: 0.46 | H31: =IF(F31="","No reviews",IF(F31>=20,"High",IF(F31>=5,"Medium","Low"))) -> No reviews | I31: =IF(G31="","Not Rated",IF(G31<3,"Poor",IF(G31<4,"Average","Excellent"))) -> Not Rated | J31: =IF(E31<0.2,"Low Discount",IF(E31<0.4,"Medium Discount","High Discount")) -> High Discount | K31: =IF(B31<500,"Low",IF(B31<1500,"Medium",IF(B31<3000,"High","Premium"))) -> High
A32: Exfoliate And Exfoliate Face Towel - Black | B32: 185 | C32: 382 | D32: 197 | E32: 0.52 | F32: 9 | G32: 4.3 | H32: =IF(F32="","No reviews",IF(F32>=20,"High",IF(F32>=5,"Medium","Low"))) -> Medium | I32: =IF(G32="","Not Rated",IF(G32<3,"Poor",IF(G32<4,"Average","Excellent"))) -> Excellent | J32: =IF(E32<0.2,"Low Discount",IF(E32<0.4,"Medium Discount","High Discount")) -> High Discount | K32: =IF(B32<500,"Low",IF(B32<1500,"Medium",IF(B32<3000,"High","Premium"))) -> Low
A33: 12 Litre Insulated Lunch Box Grey | B33: 980 | C33: 1490 | D33: 510 | E33: 0.34 | F33: 12 | G33: 4.7 | H33: =IF(F33="","No reviews",IF(F33>=20,"High",IF(F33>=5,"Medium","Low"))) -> Medium | I33: =IF(G33="","Not Rated",IF(G33<3,"Poor",IF(G33<4,"Average","Excellent"))) -> Excellent | J33: =IF(E33<0.2,"Low Discount",IF(E33<0.4,"Medium Discount","High Discount")) -> Medium Discount | K33: =IF(B33<500,"Low",IF(B33<1500,"Medium",IF(B33<3000,"High","Premium"))) -> Medium
A34: LED Eye Protection Desk Lamp , Study, Reading, USB Fan - Double Pen Holder | B34: 1820 | C34: 3490 | D34: 1670 | E34: 0.48 | F34: 9 | G34: 4.3 | H34: =IF(F34="","No reviews",IF(F34>=20,"High",IF(F34>=5,"Medium","Low"))) -> Medium | I34: =IF(G34="","Not Rated",IF(G34<3,"Poor",IF(G34<4,"Average","Excellent"))) -> Excellent | J34: =IF(E34<0.2,"Low Discount",IF(E34<0.4,"Medium Discount","High Discount")) -> High Discount | K34: =IF(B34<500,"Low",IF(B34<1500,"Medium",IF(B34<3000,"High","Premium"))) -> High
A35: 53Pcs/Set Yarn Knitting Crochet Hooks With Bag - Fortune Cat | B35: 1940 | C35: 2650 | D35: 710 | E35: 0.27 | F35: 20 | G35: 4.7 | H35: =IF(F35="","No reviews",IF(F35>=20,"High",IF(F35>=5,"Medium","Low"))) -> High | I35: =IF(G35="","Not Rated",IF(G35<3,"Poor",IF(G35<4,"Average","Excellent"))) -> Excellent | J35: =IF(E35<0.2,"Low Discount",IF(E35<0.4,"Medium Discount","High Discount")) -> Medium Discount | K35: =IF(B35<500,"Low",IF(B35<1500,"Medium",IF(B35<3000,"High","Premium"))) -> High
A36: 53 Pieces/Set Yarn Knitting Crochet Hooks With Bag - Pansies | B36: 1980 | C36: 2699 | D36: 719 | E36: 0.27 | F36: 32 | G36: 4.5 | H36: =IF(F36="","No reviews",IF(F36>=20,"High",IF(F36>=5,"Medium","Low"))) -> High | I36: =IF(G36="","Not Rated",IF(G36<3,"Poor",IF(G36<4,"Average","Excellent"))) -> Excellent | J36: =IF(E36<0.2,"Low Discount",IF(E36<0.4,"Medium Discount","High Discount")) -> Medium Discount | K36: =IF(B36<500,"Low",IF(B36<1500,"Medium",IF(B36<3000,"High","Premium"))) -> High
A37: DIY File Folder, Office Drawer File Holder, Pen Holder, Desktop Storage Rack | B37: 1620 | C37: 2690 | D37: 1070 | E37: 0.4 | F37: 1 | G37: 5 | H37: =IF(F37="","No reviews",IF(F37>=20,"High",IF(F37>=5,"Medium","Low"))) -> Low | I37: =IF(G37="","Not Rated",IF(G37<3,"Poor",IF(G37<4,"Average","Excellent"))) -> Excellent | J37: =IF(E37<0.2,"Low Discount",IF(E37<0.4,"Medium Discount","High Discount")) -> High Discount | K37: =IF(B37<500,"Low",IF(B37<1500,"Medium",IF(B37<3000,"High","Premium"))) -> High
A38: Classic Black Cat Cotton Hemp Pillow Case For Home Car | B38: 1800 | C38: 360 | D38: -1440 | E38: 0.53 | F38: 2 | G38: 5 | H38: =IF(F38="","No reviews",IF(F38>=20,"High",IF(F38>=5,"Medium","Low"))) -> Low | I38: =IF(G38="","Not Rated",IF(G38<3,"Poor",IF(G38<4,"Average","Excellent"))) -> Excellent | J38: =IF(E38<0.2,"Low Discount",IF(E38<0.4,"Medium Discount","High Discount")) -> High Discount | K38: =IF(B38<500,"Low",IF(B38<1500,"Medium",IF(B38<3000,"High","Premium"))) -> High
A39: Punch-free Great Load Bearing Bathroom Storage Rack Wall Shelf-White | B39: 389 | C39: 656 | D39: 267 | E39: 0.41 | F39: 36 | G39: 4.3 | H39: =IF(F39="","No reviews",IF(F39>=20,"High",IF(F39>=5,"Medium","Low"))) -> High | I39: =IF(G39="","Not Rated",IF(G39<3,"Poor",IF(G39<4,"Average","Excellent"))) -> Excellent | J39: =IF(E39<0.2,"Low Discount",IF(E39<0.4,"Medium Discount","High Discount")) -> High Discount | K39: =IF(B39<500,"Low",IF(B39<1500,"Medium",IF(B39<3000,"High","Premium"))) -> Low
A40: 1/2/3 Seater Elastic Sofa Cover,Living Room/Home Decor Chair Cover-Grey | B40: 1800 | C40: 2700 | D40: 900 | E40: 0.38 | F40: 2 | G40: 4.5 | H40: =IF(F40="","No reviews",IF(F40>=20,"High",IF(F40>=5,"Medium","Low"))) -> Low | I40: =IF(G40="","Not Rated",IF(G40<3,"Poor",IF(G40<4,"Average","Excellent"))) -> Excellent | J40: =IF(E40<0.2,"Low Discount",IF(E40<0.4,"Medium Discount","High Discount")) -> Medium Discount | K40: =IF(B40<500,"Low",IF(B40<1500,"Medium",IF(B40<3000,"High","Premium"))) -> High
A41: LASA Stainless Steel Double Wall Mount Soap Dispenser - 500ml | B41: 2750 | C41: 4471 | D41: 1721 | E41: 0.38 | H41: =IF(F41="","No reviews",IF(F41>=20,"High",IF(F41>=5,"Medium","Low"))) -> No reviews | I41: =IF(G41="","Not Rated",IF(G41<3,"Poor",IF(G41<4,"Average","Excellent"))) -> Not Rated | J41: =IF(E41<0.2,"Low Discount",IF(E41<0.4,"Medium Discount","High Discount")) -> Medium Discount | K41: =IF(B41<500,"Low",IF(B41<1500,"Medium",IF(B41<3000,"High","Premium"))) -> High
A42: 4M Float Switch Water Level Controller -Water Tank | B42: 475 | C42: 931 | D42: 456 | E42: 0.49 | H42: =IF(F42="","No reviews",IF(F42>=20,"High",IF(F42>=5,"Medium","Low"))) -> No reviews | I42: =IF(G42="","Not Rated",IF(G42<3,"Poor",IF(G42<4,"Average","Excellent"))) -> Not Rated | J42: =IF(E42<0.2,"Low Discount",IF(E42<0.4,"Medium Discount","High Discount")) -> High Discount | K42: =IF(B42<500,"Low",IF(B42<1500,"Medium",IF(B42<3000,"High","Premium"))) -> Low
A43: Modern Sofa Throw Pillow Cover-45x45cm-Blue&Red | B43: 238 | C43: 476 | D43: 238 | E43: 0.5 | H43: =IF(F43="","No reviews",IF(F43>=20,"High",IF(F43>=5,"Medium","Low"))) -> No reviews | I43: =IF(G43="","Not Rated",IF(G43<3,"Poor",IF(G43<4,"Average","Excellent"))) -> Not Rated | J43: =IF(E43<0.2,"Low Discount",IF(E43<0.4,"Medium Discount","High Discount")) -> High Discount | K43: =IF(B43<500,"Low",IF(B43<1500,"Medium",IF(B43<3000,"High","Premium"))) -> Low
A44: Balloon Insert, Birthday Party Balloon Set, PU Leather | B44: 610 | C44: 1060 | D44: 450 | E44: 0.42 | H44: =IF(F44="","No reviews",IF(F44>=20,"High",IF(F44>=5,"Medium","Low"))) -> No reviews | I44: =IF(G44="","Not Rated",IF(G44<3,"Poor",IF(G44<4,"Average","Excellent"))) -> Not Rated | J44: =IF(E44<0.2,"Low Discount",IF(E44<0.4,"Medium Discount","High Discount")) -> High Discount | K44: =IF(B44<500,"Low",IF(B44<1500,"Medium",IF(B44<3000,"High","Premium"))) -> Medium
A45: Shower Cap Wide Elastic Band Cover Reusable Bashroom Cap | B45: 2132 | C45: 2169 | D45: 37 | E45: 0.02 | H45: =IF(F45="","No reviews",IF(F45>=20,"High",IF(F45>=5,"Medium","Low"))) -> No reviews | I45: =IF(G45="","Not Rated",IF(G45<3,"Poor",IF(G45<4,"Average","Excellent"))) -> Not Rated | J45: =IF(E45<0.2,"Low Discount",IF(E45<0.4,"Medium Discount","High Discount")) -> Low Discount | K45: =IF(B45<500,"Low",IF(B45<1500,"Medium",IF(B45<3000,"High","Premium"))) -> High
A46: Christmas Elk Fence Yard Lawn Decorations Cute For Holidays | B46: 999 | C46: 2000 | D46: 1001 | E46: 0.5 | H46: =IF(F46="","No reviews",IF(F46>=20,"High",IF(F46>=5,"Medium","Low"))) -> No reviews | I46: =IF(G46="","Not Rated",IF(G46<3,"Poor",IF(G46<4,"Average","Excellent"))) -> Not Rated | J46: =IF(E46<0.2,"Low Discount",IF(E46<0.4,"Medium Discount","High Discount")) -> High Discount | K46: =IF(B46<500,"Low",IF(B46<1500,"Medium",IF(B46<3000,"High","Premium"))) -> Medium
A47: 60W Hot Melt Glue Sprayer - Efficient And Stable Glue Dispensing | B47: 1190 | C47: 1785 | D47: 595 | E47: 0.33 | H47: =IF(F47="","No reviews",IF(F47>=20,"High",IF(F47>=5,"Medium","Low"))) -> No reviews | I47: =IF(G47="","Not Rated",IF(G47<3,"Poor",IF(G47<4,"Average","Excellent"))) -> Not Rated | J47: =IF(E47<0.2,"Low Discount",IF(E47<0.4,"Medium Discount","High Discount")) -> Medium Discount | K47: =IF(B47<500,"Low",IF(B47<1500,"Medium",IF(B47<3000,"High","Premium"))) -> Medium
A48: Car Phone Charging Stand | B48: 671 | C48: 1316 | D48: 645 | E48: 0.49 | H48: =IF(F48="","No reviews",IF(F48>=20,"High",IF(F48>=5,"Medium","Low"))) -> No reviews | I48: =IF(G48="","Not Rated",IF(G48<3,"Poor",IF(G48<4,"Average","Excellent"))) -> Not Rated | J48: =IF(E48<0.2,"Low Discount",IF(E48<0.4,"Medium Discount","High Discount")) -> High Discount | K48: =IF(B48<500,"Low",IF(B48<1500,"Medium",IF(B48<3000,"High","Premium"))) -> Medium
...

Sheet Analysis
A1: THRESHOLDS (used by Cleaned_Data categories)
A2: Price_Q1(25th percentile) | B2: =QUARTILE(Cleaned_data!B2:B113,1) -> 500.5
A3: Price_Q3(75th percentile) | B3: =QUARTILE(Cleaned_data!B2:B113,3) -> 1693
A6: KEY PERFORMANCE INDICATORS
A7: Total products | B7: =COUNTA(Cleaned_data!B2:B113) -> 112
A8: Average current price (KSh) | B8: =AVERAGE(Cleaned_data!B2:B113) -> 1201.4375
A9: Average old price (KSh) | B9: =AVERAGE(Cleaned_data!C2:C113) -> 1811.1071
A10: Average discount_price | B10: =AVERAGE(Cleaned_data!D2:D1113) -> 609.66964
A11: Average discount | B11: =AVERAGE(Cleaned_data!E2:E113) -> 0.36776786
A12: Average rating | B12: =AVERAGE(Cleaned_data!G2:G113) -> 3.8894737
A13: Total Reviews | B13: =SUM(Cleaned_data!F2:F113) -> 723
A14: Most Expensive price (ksh) | B14: =MAX(Cleaned_data!B2:B113) -> 3750
A15: Most Expensive product | B15: =INDEX(Cleaned_data!A2:A113,MATCH(MAX(Cleaned_data!B2:B113),Cleaned_data!B2:B113,0)) -> 32PCS Portable Cordless Drill Set With Cyclic Battery Drive -26 Variable Speed
A16: Least Expensive price(ksh) | B16: =MIN(Cleaned_data!B2:B113) -> 38
A17: least Expensive product | B17: =INDEX(Cleaned_data!A2:A113,MATCH(MIN(Cleaned_data!B2:B113),Cleaned_data!B2:B113,0)) -> 3PCS Single Head Knitting Crochet Sweater Needle Set
A18: Average discount percentage. | B18: =AVERAGE(Cleaned_data!E2:E113) -> 0.36776786
A19: CORRELATION ANALYSIS
A20: Discount vs Review | B20: =CORREL(Cleaned_data!E2:E113,Cleaned_data!F2:F113) -> -0.13682272
A21: Rating vs Review | B21: =CORREL(Cleaned_data!G2:G113,Cleaned_data!F2:F113) -> 0.057209035
A22: Current Price vs Rating | B22: =CORREL(Cleaned_data!B2:B113,Cleaned_data!G2:G113) -> 0.14959837
A24: RANKED PRODUCT TABLES
A25: Top 5 products by Rating
A26: {=INDEX(_xlfn.SORTBY(Cleaned_data!A2:A113, Cleaned_data!G2:G113, -1, Cleaned_data!F2:F113, -1), _xlfn.SEQUENCE(5))} -> 4pcs Bathroom/Kitchen Towel Rack,Roll Paper Holder,Towel Bars,Hook
A27: MultiFunctional Storage Rack Multi-layer Bookshelf
A28: LASA Stainless Steel Double Wall Mount Soap Dispenser - 500ml
A29: 4M Float Switch Water Level Controller -Water Tank
A30: Modern Sofa Throw Pillow Cover-45x45cm-Blue&Red
A32: Top 5 products with lowest Rating
A33: {=INDEX(_xlfn.SORTBY(Cleaned_data!A2:A113, Cleaned_data!G2:G113, 1, Cleaned_data!F2:F113, -1), _xlfn.SEQUENCE(5))} -> Wall-mounted Sticker Punch-free Plug Fixer
A34: 5-PCS Stainless Steel Cooking Pot Set With Steamed Slices
A35: Electric LED UV Mosquito Killer Lamp, Outdoor/Indoor Fly Killer Trap Light -USB
A36: Artificial Potted Flowers Room Decorative Flowers (2 Pieces)
A37: 7-piece Set Of Storage Bags, Travel Storage Bags, Shoe Bags
A39: Top 10 by Discount
A40: {=INDEX(_xlfn.SORTBY(Cleaned_data!A2:A113, Cleaned_data!E2:E113, -1), _xlfn.SEQUENCE(10))} -> 6 In 1 Bottle Can Opener Multifunctional Easy Opener
A41: Creative Owl Shape Keychain Black
A42: LASA FOLDING TABLE SERVING STAND
A43: Simple Metal Dog Art Sculpture Decoration For Home Office
A44: 5-PCS Stainless Steel Cooking Pot Set With Steamed Slices
A45: LASA 3 Tier Bamboo Shoe Bench Storage Shelf
...
